<?xml version="1.0"?>
<robot name="my_robot">

  <material name="azul"><color rgba="0.2 0.6 1.0 1.0"/></material>
  <material name="preto"><color rgba="0.1 0.1 0.1 1.0"/></material>

  <!-- Chassis: origem no centro geométrico da caixa -->
  <link name="base_link">
    <visual>
      <geometry><box size="0.4 0.2 0.1"/></geometry>
      <material name="azul"/>
    </visual>
    <collision>
      <geometry><box size="0.4 0.2 0.1"/></geometry>
    </collision>
    <inertial>
      <mass value="1.0"/>
      <inertia ixx="0.01" ixy="0" ixz="0" iyy="0.01" iyz="0" izz="0.01"/>
    </inertial>
  </link>

  <!-- Roda esquerda -->
  <link name="left_wheel">
    <visual>
      <geometry><cylinder radius="0.1" length="0.05"/></geometry>
      <material name="preto"/>
    </visual>
    <collision>
      <geometry><cylinder radius="0.1" length="0.05"/></geometry>
    </collision>
    <inertial>
      <mass value="0.1"/>
      <inertia ixx="0.0043" ixy="0" ixz="0" iyy="0.0043" iyz="0" izz="0.005"/>
    </inertial>
  </link>

  <joint name="left_wheel_joint" type="continuous">
    <parent link="base_link"/>
    <child link="left_wheel"/>
    <origin xyz="0.1 0.13 0.0" rpy="1.5707 0 0"/>
    <axis xyz="0 0 -1"/>
  </joint>

  <!-- Roda direita -->
  <link name="right_wheel">
    <visual>
      <geometry><cylinder radius="0.1" length="0.05"/></geometry>
      <material name="preto"/>
    </visual>
    <collision>
      <geometry><cylinder radius="0.1" length="0.05"/></geometry>
    </collision>
    <inertial>
      <mass value="0.1"/>
      <inertia ixx="0.0043" ixy="0" ixz="0" iyy="0.0043" iyz="0" izz="0.005"/>
    </inertial>
  </link>

  <joint name="right_wheel_joint" type="continuous">
    <parent link="base_link"/>
    <child link="right_wheel"/>
    <origin xyz="0.1 -0.13 0.0" rpy="1.5707 0 0"/>
    <axis xyz="0 0 -1"/>
  </joint>

  <!-- Caster traseiro -->
  <link name="caster_link">
    <visual>
      <geometry><sphere radius="0.05"/></geometry>
      <material name="preto"/>
    </visual>
    <collision>
      <geometry><sphere radius="0.05"/></geometry>
    </collision>
    <inertial>
      <mass value="0.01"/>
      <inertia ixx="0.0001" ixy="0" ixz="0" iyy="0.0001" iyz="0" izz="0.0001"/>
    </inertial>
  </link>

  <joint name="caster_joint" type="fixed">
    <parent link="base_link"/>
    <child link="caster_link"/>
    <origin xyz="-0.15 0 -0.05"/>
  </joint>

  <!-- Sem atrito no caster -->
  <gazebo reference="caster_link">
    <mu1>0</mu1>
    <mu2>0</mu2>
    <slip1>1.0</slip1>
    <slip2>1.0</slip2>
  </gazebo>

  <!-- Plugin diff drive -->
  <gazebo>
    <plugin name="differential_drive_controller" filename="libgazebo_ros_diff_drive.so">
      <left_joint>left_wheel_joint</left_joint>
      <right_joint>right_wheel_joint</right_joint>
      <wheel_separation>0.26</wheel_separation>
      <wheel_diameter>0.2</wheel_diameter>
      <max_wheel_torque>20</max_wheel_torque>
      <max_wheel_acceleration>1.0</max_wheel_acceleration>
      <command_topic>cmd_vel</command_topic>
      <odometry_topic>odom</odometry_topic>
      <odometry_frame>odom</odometry_frame>
      <robot_base_frame>base_link</robot_base_frame>
      <publish_odom>true</publish_odom>
      <publish_odom_tf>true</publish_odom_tf>
      <update_rate>30</update_rate>
    </plugin>
  </gazebo>

</robot>
